2021-03-10 22:22:21,322 django.request ERROR    Internal Server Error: /download/create_asin_task
Traceback (most recent call last):
  File "c:\python38\lib\site-packages\django\core\handlers\exception.py", line 47, in inner
    response = get_response(request)
  File "c:\python38\lib\site-packages\django\core\handlers\base.py", line 179, in _get_response
    response = wrapped_callback(request, *callback_args, **callback_kwargs)
  File "C:\Local\Work\Web\web\amazon\download\views.py", line 79, in create_asin_task
    search_form = ASIN_Search_task_form()
  File "C:\Local\Work\Web\web\amazon\download\views.py", line 378, in __init__
    self.fields['ASIN_Name_List'].initial  = 'Bluetooth Headset'
KeyError: 'ASIN_Name_List'
2021-03-10 22:22:21,326 django.server ERROR    "GET /download/create_asin_task HTTP/1.1" 500 74545
2021-03-10 22:41:35,714 django.request WARNING  Not Found: /
2021-03-10 22:41:35,715 django.server WARNING  "GET / HTTP/1.1" 404 2030
2021-03-11 09:33:36,922 django.request ERROR    Internal Server Error: /download/show_asin_task
Traceback (most recent call last):
  File "c:\python38\lib\site-packages\django\core\handlers\exception.py", line 47, in inner
    response = get_response(request)
  File "c:\python38\lib\site-packages\django\core\handlers\base.py", line 179, in _get_response
    response = wrapped_callback(request, *callback_args, **callback_kwargs)
  File "C:\Local\Work\Web\web\amazon\download\views.py", line 190, in show_asin_task
    scheduler.handle_scrapy_start(scrapy_data)
  File "C:\Local\Work\Web\web\amazon\download\apscheduler_handle.py", line 97, in handle_scrapy_start
    self.scheduler.add_listener(self.job_completed,  EVENT_JOB_EXECUTED | EVENT_JOB_ERROR, task_id)
TypeError: add_listener() takes from 2 to 3 positional arguments but 4 were given
2021-03-11 09:33:36,926 django.server ERROR    "POST /download/show_asin_task HTTP/1.1" 500 76539
2021-03-11 15:54:54,830 django.request ERROR    Internal Server Error: /download/show_asin_task
Traceback (most recent call last):
  File "c:\python38\lib\site-packages\django\core\handlers\exception.py", line 47, in inner
    response = get_response(request)
  File "c:\python38\lib\site-packages\django\core\handlers\base.py", line 179, in _get_response
    response = wrapped_callback(request, *callback_args, **callback_kwargs)
  File "C:\Local\Work\Web\web\amazon\download\views.py", line 198, in show_asin_task
    scheduler.handle_scrapy_start(scrapy_data)
  File "C:\Local\Work\Web\web\amazon\download\apscheduler_handle.py", line 95, in handle_scrapy_start
    self.scheduler.add_listener(self.job_completed,  EVENT_JOB_EXECUTED | EVENT_JOB_ERROR,task_id)
TypeError: add_listener() takes from 2 to 3 positional arguments but 4 were given
2021-03-11 15:54:54,845 django.server ERROR    "POST /download/show_asin_task HTTP/1.1" 500 77230
2021-03-11 16:02:31,678 django.request ERROR    Internal Server Error: /download/show_asin_task
Traceback (most recent call last):
  File "c:\python38\lib\site-packages\django\core\handlers\exception.py", line 47, in inner
    response = get_response(request)
  File "c:\python38\lib\site-packages\django\core\handlers\base.py", line 179, in _get_response
    response = wrapped_callback(request, *callback_args, **callback_kwargs)
  File "C:\Local\Work\Web\web\amazon\download\views.py", line 152, in show_asin_task
    t = all_objects.get(k)
  File "c:\python38\lib\site-packages\django\db\models\query.py", line 418, in get
    clone = self._chain() if self.query.combinator else self.filter(*args, **kwargs)
  File "c:\python38\lib\site-packages\django\db\models\query.py", line 942, in filter
    return self._filter_or_exclude(False, *args, **kwargs)
  File "c:\python38\lib\site-packages\django\db\models\query.py", line 962, in _filter_or_exclude
    clone._filter_or_exclude_inplace(negate, *args, **kwargs)
  File "c:\python38\lib\site-packages\django\db\models\query.py", line 969, in _filter_or_exclude_inplace
    self._query.add_q(Q(*args, **kwargs))
  File "c:\python38\lib\site-packages\django\db\models\sql\query.py", line 1358, in add_q
    clause, _ = self._add_q(q_object, self.used_aliases)
  File "c:\python38\lib\site-packages\django\db\models\sql\query.py", line 1377, in _add_q
    child_clause, needed_inner = self.build_filter(
  File "c:\python38\lib\site-packages\django\db\models\sql\query.py", line 1255, in build_filter
    arg, value = filter_expr
ValueError: too many values to unpack (expected 2)
2021-03-11 16:02:31,688 django.server ERROR    "GET /download/show_asin_task HTTP/1.1" 500 104526
2021-03-11 16:03:55,789 django.request ERROR    Internal Server Error: /download/show_asin_task
Traceback (most recent call last):
  File "c:\python38\lib\site-packages\django\core\handlers\exception.py", line 47, in inner
    response = get_response(request)
  File "c:\python38\lib\site-packages\django\core\handlers\base.py", line 179, in _get_response
    response = wrapped_callback(request, *callback_args, **callback_kwargs)
  File "C:\Local\Work\Web\web\amazon\download\views.py", line 155, in show_asin_task
    logger.worker.warning(t.ASIN_Name_List + "Status changed")
UnboundLocalError: local variable 't' referenced before assignment
2021-03-11 16:03:55,793 django.server ERROR    "GET /download/show_asin_task HTTP/1.1" 500 70649
2021-03-11 16:19:37,521 django.request ERROR    Internal Server Error: /download/show_asin_task
Traceback (most recent call last):
  File "C:\Local\Work\Web\web\amazon\download\apscheduler_handle.py", line 113, in handle_scrapy_start
    self.process.start(False)
  File "c:\python38\lib\site-packages\scrapy\crawler.py", line 327, in start
    reactor.run(installSignalHandlers=False)  # blocking call
  File "c:\python38\lib\site-packages\twisted\internet\base.py", line 1282, in run
    self.startRunning(installSignalHandlers=installSignalHandlers)
  File "c:\python38\lib\site-packages\twisted\internet\base.py", line 1262, in startRunning
    ReactorBase.startRunning(self)
  File "c:\python38\lib\site-packages\twisted\internet\base.py", line 763, in startRunning
    raise error.ReactorAlreadyRunning()
twisted.internet.error.ReactorAlreadyRunning

During handling of the above exception, another exception occurred:

Traceback (most recent call last):
  File "c:\python38\lib\site-packages\django\core\handlers\exception.py", line 47, in inner
    response = get_response(request)
  File "c:\python38\lib\site-packages\django\core\handlers\base.py", line 179, in _get_response
    response = wrapped_callback(request, *callback_args, **callback_kwargs)
  File "C:\Local\Work\Web\web\amazon\download\views.py", line 198, in show_asin_task
    scheduler.handle_scrapy_start(scrapy_data)
  File "C:\Local\Work\Web\web\amazon\download\apscheduler_handle.py", line 116, in handle_scrapy_start
    logger.info("already run")
AttributeError: 'Logger' object has no attribute 'info'
2021-03-11 16:19:37,528 django.server ERROR    "POST /download/show_asin_task HTTP/1.1" 500 97927
2021-03-11 23:41:18,984 django.request ERROR    Internal Server Error: /download/show_asin_task
Traceback (most recent call last):
  File "c:\python38\lib\site-packages\django\core\handlers\exception.py", line 47, in inner
    response = get_response(request)
  File "c:\python38\lib\site-packages\django\core\handlers\base.py", line 179, in _get_response
    response = wrapped_callback(request, *callback_args, **callback_kwargs)
  File "C:\Local\Work\Web\web\amazon\download\views.py", line 198, in show_asin_task
    scheduler.handle_scrapy_start(scrapy_data)
  File "C:\Local\Work\Web\web\amazon\download\apscheduler_handle.py", line 102, in handle_scrapy_start
    self.scheduler.add_job(self.process.crawl, args=[StackSpider,asin_list])
NameError: name 'asin_list' is not defined
2021-03-11 23:41:19,001 django.server ERROR    "POST /download/show_asin_task HTTP/1.1" 500 76831
2021-03-11 23:43:08,006 django.request ERROR    Internal Server Error: /download/show_asin_task
Traceback (most recent call last):
  File "c:\python38\lib\site-packages\django\core\handlers\exception.py", line 47, in inner
    response = get_response(request)
  File "c:\python38\lib\site-packages\django\core\handlers\base.py", line 179, in _get_response
    response = wrapped_callback(request, *callback_args, **callback_kwargs)
  File "C:\Local\Work\Web\web\amazon\download\views.py", line 198, in show_asin_task
    scheduler.handle_scrapy_start(scrapy_data)
  File "C:\Local\Work\Web\web\amazon\download\apscheduler_handle.py", line 106, in handle_scrapy_start
    self.scheduler.add_job(self.process.crawl, args=[StackSpider,asin_list])
NameError: name 'asin_list' is not defined
2021-03-11 23:43:08,016 django.server ERROR    "POST /download/show_asin_task HTTP/1.1" 500 76930
2021-03-11 23:45:49,844 django.request ERROR    Internal Server Error: /download/show_asin_task
Traceback (most recent call last):
  File "c:\python38\lib\site-packages\django\core\handlers\exception.py", line 47, in inner
    response = get_response(request)
  File "c:\python38\lib\site-packages\django\core\handlers\base.py", line 179, in _get_response
    response = wrapped_callback(request, *callback_args, **callback_kwargs)
  File "C:\Local\Work\Web\web\amazon\download\views.py", line 207, in show_asin_task
    context=load_asin_json(asin_list,context)
  File "C:\Local\Work\Web\web\amazon\download\asin_json_process.py", line 56, in load_asin_json
    dict=json_lib.load_json(file)
  File "C:\Local\Work\Python\PyLib\json_lib.py", line 24, in load_json
    with open(file_name, encoding='utf-8', mode="r") as file:
FileNotFoundError: [Errno 2] No such file or directory: 'download\\json_result\\B08DDZZRJF.json'
2021-03-11 23:45:49,856 django.server ERROR    "POST /download/show_asin_task HTTP/1.1" 500 80821
2021-03-18 18:50:38,297 django.request WARNING  Not Found: /favicon.ico
2021-03-18 18:50:38,298 django.server WARNING  "GET /favicon.ico HTTP/1.1" 404 2081
2021-03-24 21:54:12,634 django.request WARNING  Not Found: /favicon.ico
2021-03-24 21:54:12,638 django.server WARNING  "GET /favicon.ico HTTP/1.1" 404 2081
2021-03-24 21:54:26,028 django.request ERROR    Internal Server Error: /download/show_asin_task
Traceback (most recent call last):
  File "c:\python38\lib\site-packages\django\core\handlers\exception.py", line 47, in inner
    response = get_response(request)
  File "c:\python38\lib\site-packages\django\core\handlers\base.py", line 179, in _get_response
    response = wrapped_callback(request, *callback_args, **callback_kwargs)
  File "C:\Local\Work\Web\web\amazon\download\views.py", line 248, in show_asin_task
    scrapy_data=create_task_result_json(scrapy_data)
  File "C:\Local\Work\Web\web\amazon\download\asin_json_process.py", line 45, in create_task_result_json
    logger.worker.warning(json.dump(scrapy_data['result_dict']))
TypeError: dump() missing 1 required positional argument: 'fp'
2021-03-24 21:54:26,034 django.server ERROR    "POST /download/show_asin_task HTTP/1.1" 500 75744
2021-03-24 21:55:12,192 django.request ERROR    Internal Server Error: /download/show_asin_task
Traceback (most recent call last):
  File "c:\python38\lib\site-packages\django\core\handlers\exception.py", line 47, in inner
    response = get_response(request)
  File "c:\python38\lib\site-packages\django\core\handlers\base.py", line 179, in _get_response
    response = wrapped_callback(request, *callback_args, **callback_kwargs)
  File "C:\Local\Work\Web\web\amazon\download\views.py", line 248, in show_asin_task
    scrapy_data=create_task_result_json(scrapy_data)
  File "C:\Local\Work\Web\web\amazon\download\asin_json_process.py", line 45, in create_task_result_json
    logger.worker.warning(json.dumps(scrapy_data['result_dict']))
  File "C:\Python38\lib\json\__init__.py", line 231, in dumps
    return _default_encoder.encode(obj)
  File "C:\Python38\lib\json\encoder.py", line 199, in encode
    chunks = self.iterencode(o, _one_shot=True)
  File "C:\Python38\lib\json\encoder.py", line 257, in iterencode
    return _iterencode(o, 0)
  File "C:\Python38\lib\json\encoder.py", line 179, in default
    raise TypeError(f'Object of type {o.__class__.__name__} '
TypeError: Object of type date is not JSON serializable
2021-03-24 21:55:12,201 django.server ERROR    "POST /download/show_asin_task HTTP/1.1" 500 95170
2021-03-24 21:56:54,062 django.request ERROR    Internal Server Error: /download/show_asin_task
Traceback (most recent call last):
  File "c:\python38\lib\site-packages\django\core\handlers\exception.py", line 47, in inner
    response = get_response(request)
  File "c:\python38\lib\site-packages\django\core\handlers\base.py", line 179, in _get_response
    response = wrapped_callback(request, *callback_args, **callback_kwargs)
  File "C:\Local\Work\Web\web\amazon\download\views.py", line 250, in show_asin_task
    scheduler.handle_scrapy_start(scrapy_data)
  File "C:\Local\Work\Web\web\amazon\download\apscheduler_handle.py", line 113, in handle_scrapy_start
    self.task_id=scrapy_data['task_id']
TypeError: 'NoneType' object is not subscriptable
2021-03-24 21:56:54,066 django.server ERROR    "POST /download/show_asin_task HTTP/1.1" 500 75073
2021-03-24 21:57:18,538 django.request ERROR    Internal Server Error: /download/show_asin_task
Traceback (most recent call last):
  File "c:\python38\lib\site-packages\django\core\handlers\exception.py", line 47, in inner
    response = get_response(request)
  File "c:\python38\lib\site-packages\django\core\handlers\base.py", line 179, in _get_response
    response = wrapped_callback(request, *callback_args, **callback_kwargs)
  File "C:\Local\Work\Web\web\amazon\download\views.py", line 248, in show_asin_task
    scrapy_data=create_task_result_json(scrapy_data)
  File "C:\Local\Work\Web\web\amazon\download\asin_json_process.py", line 49, in create_task_result_json
    logger.worker.warning(json.dumps(scrapy_data['result_dict']))
  File "C:\Python38\lib\json\__init__.py", line 231, in dumps
    return _default_encoder.encode(obj)
  File "C:\Python38\lib\json\encoder.py", line 199, in encode
    chunks = self.iterencode(o, _one_shot=True)
  File "C:\Python38\lib\json\encoder.py", line 257, in iterencode
    return _iterencode(o, 0)
  File "C:\Python38\lib\json\encoder.py", line 179, in default
    raise TypeError(f'Object of type {o.__class__.__name__} '
TypeError: Object of type set is not JSON serializable
2021-03-24 21:57:18,546 django.server ERROR    "POST /download/show_asin_task HTTP/1.1" 500 92424
2021-03-24 21:58:27,549 django.request ERROR    Internal Server Error: /download/show_asin_task
Traceback (most recent call last):
  File "c:\python38\lib\site-packages\django\core\handlers\exception.py", line 47, in inner
    response = get_response(request)
  File "c:\python38\lib\site-packages\django\core\handlers\base.py", line 179, in _get_response
    response = wrapped_callback(request, *callback_args, **callback_kwargs)
  File "C:\Local\Work\Web\web\amazon\download\views.py", line 250, in show_asin_task
    scheduler.handle_scrapy_start(scrapy_data)
  File "C:\Local\Work\Web\web\amazon\download\apscheduler_handle.py", line 113, in handle_scrapy_start
    self.task_id=scrapy_data['task_id']
TypeError: 'NoneType' object is not subscriptable
2021-03-24 21:58:27,555 django.server ERROR    "POST /download/show_asin_task HTTP/1.1" 500 75075
2021-03-24 22:00:34,984 django.request ERROR    Internal Server Error: /download/show_asin_task
Traceback (most recent call last):
  File "c:\python38\lib\site-packages\django\core\handlers\exception.py", line 47, in inner
    response = get_response(request)
  File "c:\python38\lib\site-packages\django\core\handlers\base.py", line 179, in _get_response
    response = wrapped_callback(request, *callback_args, **callback_kwargs)
  File "C:\Local\Work\Web\web\amazon\download\views.py", line 250, in show_asin_task
    scheduler.handle_scrapy_start(scrapy_data)
  File "C:\Local\Work\Web\web\amazon\download\apscheduler_handle.py", line 113, in handle_scrapy_start
    self.task_id=scrapy_data['task_id']
TypeError: 'NoneType' object is not subscriptable
2021-03-24 22:00:34,992 django.server ERROR    "POST /download/show_asin_task HTTP/1.1" 500 75072
2021-03-24 22:02:18,431 django.request ERROR    Internal Server Error: /download/show_asin_task
Traceback (most recent call last):
  File "c:\python38\lib\site-packages\django\core\handlers\exception.py", line 47, in inner
    response = get_response(request)
  File "c:\python38\lib\site-packages\django\core\handlers\base.py", line 179, in _get_response
    response = wrapped_callback(request, *callback_args, **callback_kwargs)
  File "C:\Local\Work\Web\web\amazon\download\views.py", line 251, in show_asin_task
    scheduler.handle_scrapy_start(scrapy_data)
  File "C:\Local\Work\Web\web\amazon\download\apscheduler_handle.py", line 113, in handle_scrapy_start
    self.task_id=scrapy_data['task_id']
TypeError: 'NoneType' object is not subscriptable
2021-03-24 22:02:18,436 django.server ERROR    "POST /download/show_asin_task HTTP/1.1" 500 75114
2021-03-24 22:03:37,856 django.request ERROR    Internal Server Error: /download/show_asin_task
Traceback (most recent call last):
  File "c:\python38\lib\site-packages\django\core\handlers\exception.py", line 47, in inner
    response = get_response(request)
  File "c:\python38\lib\site-packages\django\core\handlers\base.py", line 179, in _get_response
    response = wrapped_callback(request, *callback_args, **callback_kwargs)
  File "C:\Local\Work\Web\web\amazon\download\views.py", line 250, in show_asin_task
    scheduler.handle_scrapy_start(scrapy_data)
  File "C:\Local\Work\Web\web\amazon\download\apscheduler_handle.py", line 109, in handle_scrapy_start
    logger.worker.warning(scrapy_data['task_id'])
TypeError: 'NoneType' object is not subscriptable
2021-03-24 22:03:37,861 django.server ERROR    "POST /download/show_asin_task HTTP/1.1" 500 75094
2021-03-24 22:04:42,047 django.request ERROR    Internal Server Error: /download/show_asin_task
Traceback (most recent call last):
  File "c:\python38\lib\site-packages\django\core\handlers\exception.py", line 47, in inner
    response = get_response(request)
  File "c:\python38\lib\site-packages\django\core\handlers\base.py", line 179, in _get_response
    response = wrapped_callback(request, *callback_args, **callback_kwargs)
  File "C:\Local\Work\Web\web\amazon\download\views.py", line 250, in show_asin_task
    scheduler.handle_scrapy_start(scrapy_data)
  File "C:\Local\Work\Web\web\amazon\download\apscheduler_handle.py", line 110, in handle_scrapy_start
    logger.worker.warning(scrapy_data['task_id'])
TypeError: 'NoneType' object is not subscriptable
2021-03-24 22:04:42,051 django.server ERROR    "POST /download/show_asin_task HTTP/1.1" 500 75067
2021-03-24 22:05:31,944 django.request ERROR    Internal Server Error: /download/show_asin_task
Traceback (most recent call last):
  File "c:\python38\lib\site-packages\django\core\handlers\exception.py", line 47, in inner
    response = get_response(request)
  File "c:\python38\lib\site-packages\django\core\handlers\base.py", line 179, in _get_response
    response = wrapped_callback(request, *callback_args, **callback_kwargs)
  File "C:\Local\Work\Web\web\amazon\download\views.py", line 250, in show_asin_task
    scheduler.handle_scrapy_start(scrapy_data)
  File "C:\Local\Work\Web\web\amazon\download\apscheduler_handle.py", line 115, in handle_scrapy_start
    self.task_id=scrapy_data['task_id']
TypeError: 'NoneType' object is not subscriptable
2021-03-24 22:05:31,950 django.server ERROR    "POST /download/show_asin_task HTTP/1.1" 500 75085
2021-03-25 00:59:33,768 django.request ERROR    Internal Server Error: /download/show_asin_task
Traceback (most recent call last):
  File "c:\python38\lib\site-packages\django\core\handlers\exception.py", line 47, in inner
    response = get_response(request)
  File "c:\python38\lib\site-packages\django\core\handlers\base.py", line 179, in _get_response
    response = wrapped_callback(request, *callback_args, **callback_kwargs)
  File "C:\Local\Work\Web\web\amazon\download\views.py", line 250, in show_asin_task
    scrapy_data=create_task_result_json(scrapy_data)
  File "C:\Local\Work\Web\web\amazon\download\asin_json_process.py", line 51, in create_task_result_json
    logger.worker.warning(json.dumps(scrapy_data))
  File "C:\Python38\lib\json\__init__.py", line 231, in dumps
    return _default_encoder.encode(obj)
  File "C:\Python38\lib\json\encoder.py", line 199, in encode
    chunks = self.iterencode(o, _one_shot=True)
  File "C:\Python38\lib\json\encoder.py", line 257, in iterencode
    return _iterencode(o, 0)
  File "C:\Python38\lib\json\encoder.py", line 179, in default
    raise TypeError(f'Object of type {o.__class__.__name__} '
TypeError: Object of type date is not JSON serializable
2021-03-25 00:59:33,774 django.server ERROR    "POST /download/show_asin_task HTTP/1.1" 500 93437
2021-04-01 03:16:47,964 django.request WARNING  Not Found: /favicon.ico
2021-04-01 03:16:47,964 django.server WARNING  "GET /favicon.ico HTTP/1.1" 404 2081
2021-04-01 03:27:25,245 django.request ERROR    Internal Server Error: /download/create_asin_task
Traceback (most recent call last):
  File "c:\python38\lib\site-packages\django\core\handlers\exception.py", line 47, in inner
    response = get_response(request)
  File "c:\python38\lib\site-packages\django\core\handlers\base.py", line 179, in _get_response
    response = wrapped_callback(request, *callback_args, **callback_kwargs)
  File "C:\Local\Work\Web\web\amazon\download\views.py", line 150, in create_asin_task
    form = ASIN_task_form()
  File "C:\Local\Work\Web\web\amazon\download\views.py", line 92, in __init__
    self.fields['Start_Time'].initial  = start
NameError: name 'start' is not defined
2021-04-01 03:27:25,249 django.server ERROR    "GET /download/create_asin_task HTTP/1.1" 500 72354
2021-04-01 03:49:48,934 django.request ERROR    Internal Server Error: /download/show_asin_detail
Traceback (most recent call last):
  File "c:\python38\lib\site-packages\django\core\handlers\exception.py", line 47, in inner
    response = get_response(request)
  File "c:\python38\lib\site-packages\django\core\handlers\base.py", line 179, in _get_response
    response = wrapped_callback(request, *callback_args, **callback_kwargs)
  File "C:\Local\Work\Web\web\amazon\download\views.py", line 508, in show_asin_detail
    'ID': data["ASIN"],
KeyError: 'ASIN'
2021-04-01 03:49:48,938 django.server ERROR    "GET /download/show_asin_detail HTTP/1.1" 500 67762
2021-04-01 03:52:02,686 django.request ERROR    Internal Server Error: /download/show_asin_detail
Traceback (most recent call last):
  File "c:\python38\lib\site-packages\django\core\handlers\exception.py", line 47, in inner
    response = get_response(request)
  File "c:\python38\lib\site-packages\django\core\handlers\base.py", line 179, in _get_response
    response = wrapped_callback(request, *callback_args, **callback_kwargs)
  File "C:\Local\Work\Web\web\amazon\download\views.py", line 514, in show_asin_detail
    logger.worker.warning('log in show asin detail!')
AttributeError: 'Logger' object has no attribute 'worker'
2021-04-01 03:52:02,690 django.server ERROR    "GET /download/show_asin_detail HTTP/1.1" 500 68664
2021-04-01 03:56:03,490 django.request ERROR    Internal Server Error: /download/show_asin_task
Traceback (most recent call last):
  File "c:\python38\lib\site-packages\django\db\backends\utils.py", line 84, in _execute
    return self.cursor.execute(sql, params)
  File "c:\python38\lib\site-packages\django\db\backends\sqlite3\base.py", line 413, in execute
    return Database.Cursor.execute(self, query, params)
sqlite3.IntegrityError: NOT NULL constraint failed: download_asin_task.End_Time

The above exception was the direct cause of the following exception:

Traceback (most recent call last):
  File "c:\python38\lib\site-packages\django\core\handlers\exception.py", line 47, in inner
    response = get_response(request)
  File "c:\python38\lib\site-packages\django\core\handlers\base.py", line 179, in _get_response
    response = wrapped_callback(request, *callback_args, **callback_kwargs)
  File "C:\Local\Work\Web\web\amazon\download\views.py", line 236, in show_asin_task
    t.save()
  File "c:\python38\lib\site-packages\django\db\models\base.py", line 753, in save
    self.save_base(using=using, force_insert=force_insert,
  File "c:\python38\lib\site-packages\django\db\models\base.py", line 790, in save_base
    updated = self._save_table(
  File "c:\python38\lib\site-packages\django\db\models\base.py", line 872, in _save_table
    updated = self._do_update(base_qs, using, pk_val, values, update_fields,
  File "c:\python38\lib\site-packages\django\db\models\base.py", line 926, in _do_update
    return filtered._update(values) > 0
  File "c:\python38\lib\site-packages\django\db\models\query.py", line 803, in _update
    return query.get_compiler(self.db).execute_sql(CURSOR)
  File "c:\python38\lib\site-packages\django\db\models\sql\compiler.py", line 1522, in execute_sql
    cursor = super().execute_sql(result_type)
  File "c:\python38\lib\site-packages\django\db\models\sql\compiler.py", line 1156, in execute_sql
    cursor.execute(sql, params)
  File "c:\python38\lib\site-packages\django\db\backends\utils.py", line 98, in execute
    return super().execute(sql, params)
  File "c:\python38\lib\site-packages\django\db\backends\utils.py", line 66, in execute
    return self._execute_with_wrappers(sql, params, many=False, executor=self._execute)
  File "c:\python38\lib\site-packages\django\db\backends\utils.py", line 75, in _execute_with_wrappers
    return executor(sql, params, many, context)
  File "c:\python38\lib\site-packages\django\db\backends\utils.py", line 84, in _execute
    return self.cursor.execute(sql, params)
  File "c:\python38\lib\site-packages\django\db\utils.py", line 90, in __exit__
    raise dj_exc_value.with_traceback(traceback) from exc_value
  File "c:\python38\lib\site-packages\django\db\backends\utils.py", line 84, in _execute
    return self.cursor.execute(sql, params)
  File "c:\python38\lib\site-packages\django\db\backends\sqlite3\base.py", line 413, in execute
    return Database.Cursor.execute(self, query, params)
django.db.utils.IntegrityError: NOT NULL constraint failed: download_asin_task.End_Time
2021-04-01 03:56:03,512 django.server ERROR    "POST /download/show_asin_task HTTP/1.1" 500 152666
2021-04-01 04:02:14,200 django.request ERROR    Internal Server Error: /download/show_asin_task
Traceback (most recent call last):
  File "c:\python38\lib\site-packages\django\db\backends\utils.py", line 84, in _execute
    return self.cursor.execute(sql, params)
  File "c:\python38\lib\site-packages\django\db\backends\sqlite3\base.py", line 413, in execute
    return Database.Cursor.execute(self, query, params)
sqlite3.IntegrityError: NOT NULL constraint failed: download_asin_task.End_Time

The above exception was the direct cause of the following exception:

Traceback (most recent call last):
  File "c:\python38\lib\site-packages\django\core\handlers\exception.py", line 47, in inner
    response = get_response(request)
  File "c:\python38\lib\site-packages\django\core\handlers\base.py", line 179, in _get_response
    response = wrapped_callback(request, *callback_args, **callback_kwargs)
  File "C:\Local\Work\Web\web\amazon\download\views.py", line 236, in show_asin_task
    t.save()
  File "c:\python38\lib\site-packages\django\db\models\base.py", line 753, in save
    self.save_base(using=using, force_insert=force_insert,
  File "c:\python38\lib\site-packages\django\db\models\base.py", line 790, in save_base
    updated = self._save_table(
  File "c:\python38\lib\site-packages\django\db\models\base.py", line 872, in _save_table
    updated = self._do_update(base_qs, using, pk_val, values, update_fields,
  File "c:\python38\lib\site-packages\django\db\models\base.py", line 926, in _do_update
    return filtered._update(values) > 0
  File "c:\python38\lib\site-packages\django\db\models\query.py", line 803, in _update
    return query.get_compiler(self.db).execute_sql(CURSOR)
  File "c:\python38\lib\site-packages\django\db\models\sql\compiler.py", line 1522, in execute_sql
    cursor = super().execute_sql(result_type)
  File "c:\python38\lib\site-packages\django\db\models\sql\compiler.py", line 1156, in execute_sql
    cursor.execute(sql, params)
  File "c:\python38\lib\site-packages\django\db\backends\utils.py", line 98, in execute
    return super().execute(sql, params)
  File "c:\python38\lib\site-packages\django\db\backends\utils.py", line 66, in execute
    return self._execute_with_wrappers(sql, params, many=False, executor=self._execute)
  File "c:\python38\lib\site-packages\django\db\backends\utils.py", line 75, in _execute_with_wrappers
    return executor(sql, params, many, context)
  File "c:\python38\lib\site-packages\django\db\backends\utils.py", line 84, in _execute
    return self.cursor.execute(sql, params)
  File "c:\python38\lib\site-packages\django\db\utils.py", line 90, in __exit__
    raise dj_exc_value.with_traceback(traceback) from exc_value
  File "c:\python38\lib\site-packages\django\db\backends\utils.py", line 84, in _execute
    return self.cursor.execute(sql, params)
  File "c:\python38\lib\site-packages\django\db\backends\sqlite3\base.py", line 413, in execute
    return Database.Cursor.execute(self, query, params)
django.db.utils.IntegrityError: NOT NULL constraint failed: download_asin_task.End_Time
2021-04-01 04:02:14,211 django.server ERROR    "POST /download/show_asin_task HTTP/1.1" 500 152666
2021-04-01 04:05:58,221 django.request ERROR    Internal Server Error: /download/create_asin_task
Traceback (most recent call last):
  File "c:\python38\lib\site-packages\django\db\backends\utils.py", line 84, in _execute
    return self.cursor.execute(sql, params)
  File "c:\python38\lib\site-packages\django\db\backends\sqlite3\base.py", line 413, in execute
    return Database.Cursor.execute(self, query, params)
sqlite3.OperationalError: no such table: download_asin_task

The above exception was the direct cause of the following exception:

Traceback (most recent call last):
  File "c:\python38\lib\site-packages\django\core\handlers\exception.py", line 47, in inner
    response = get_response(request)
  File "c:\python38\lib\site-packages\django\core\handlers\base.py", line 179, in _get_response
    response = wrapped_callback(request, *callback_args, **callback_kwargs)
  File "C:\Local\Work\Web\web\amazon\download\views.py", line 159, in create_asin_task
    form.save()
  File "c:\python38\lib\site-packages\django\forms\models.py", line 460, in save
    self.instance.save()
  File "c:\python38\lib\site-packages\django\db\models\base.py", line 753, in save
    self.save_base(using=using, force_insert=force_insert,
  File "c:\python38\lib\site-packages\django\db\models\base.py", line 790, in save_base
    updated = self._save_table(
  File "c:\python38\lib\site-packages\django\db\models\base.py", line 895, in _save_table
    results = self._do_insert(cls._base_manager, using, fields, returning_fields, raw)
  File "c:\python38\lib\site-packages\django\db\models\base.py", line 933, in _do_insert
    return manager._insert(
  File "c:\python38\lib\site-packages\django\db\models\manager.py", line 85, in manager_method
    return getattr(self.get_queryset(), name)(*args, **kwargs)
  File "c:\python38\lib\site-packages\django\db\models\query.py", line 1249, in _insert
    return query.get_compiler(using=using).execute_sql(returning_fields)
  File "c:\python38\lib\site-packages\django\db\models\sql\compiler.py", line 1397, in execute_sql
    cursor.execute(sql, params)
  File "c:\python38\lib\site-packages\django\db\backends\utils.py", line 98, in execute
    return super().execute(sql, params)
  File "c:\python38\lib\site-packages\django\db\backends\utils.py", line 66, in execute
    return self._execute_with_wrappers(sql, params, many=False, executor=self._execute)
  File "c:\python38\lib\site-packages\django\db\backends\utils.py", line 75, in _execute_with_wrappers
    return executor(sql, params, many, context)
  File "c:\python38\lib\site-packages\django\db\backends\utils.py", line 84, in _execute
    return self.cursor.execute(sql, params)
  File "c:\python38\lib\site-packages\django\db\utils.py", line 90, in __exit__
    raise dj_exc_value.with_traceback(traceback) from exc_value
  File "c:\python38\lib\site-packages\django\db\backends\utils.py", line 84, in _execute
    return self.cursor.execute(sql, params)
  File "c:\python38\lib\site-packages\django\db\backends\sqlite3\base.py", line 413, in execute
    return Database.Cursor.execute(self, query, params)
django.db.utils.OperationalError: no such table: download_asin_task
2021-04-01 04:05:58,235 django.server ERROR    "POST /download/create_asin_task HTTP/1.1" 500 157122
2021-04-01 04:06:32,510 django.request ERROR    Internal Server Error: /download/show_asin_detail
Traceback (most recent call last):
  File "c:\python38\lib\site-packages\django\core\handlers\exception.py", line 47, in inner
    response = get_response(request)
  File "c:\python38\lib\site-packages\django\core\handlers\base.py", line 179, in _get_response
    response = wrapped_callback(request, *callback_args, **callback_kwargs)
  File "C:\Local\Work\Web\web\amazon\download\views.py", line 514, in show_asin_detail
    logger.worker.warning('log in show asin detail!')
AttributeError: 'Logger' object has no attribute 'worker'
2021-04-01 04:06:32,514 django.server ERROR    "GET /download/show_asin_detail HTTP/1.1" 500 69165
2021-04-01 04:06:40,285 django.request ERROR    Internal Server Error: /download/show_asin_task
Traceback (most recent call last):
  File "c:\python38\lib\site-packages\django\db\backends\utils.py", line 84, in _execute
    return self.cursor.execute(sql, params)
  File "c:\python38\lib\site-packages\django\db\backends\sqlite3\base.py", line 413, in execute
    return Database.Cursor.execute(self, query, params)
sqlite3.OperationalError: no such table: download_asin_task

The above exception was the direct cause of the following exception:

Traceback (most recent call last):
  File "c:\python38\lib\site-packages\django\core\handlers\exception.py", line 47, in inner
    response = get_response(request)
  File "c:\python38\lib\site-packages\django\core\handlers\base.py", line 179, in _get_response
    response = wrapped_callback(request, *callback_args, **callback_kwargs)
  File "C:\Local\Work\Web\web\amazon\download\views.py", line 265, in show_asin_task
    return render(request, 'show_asin_task.html', context)
  File "c:\python38\lib\site-packages\django\shortcuts.py", line 19, in render
    content = loader.render_to_string(template_name, context, request, using=using)
  File "c:\python38\lib\site-packages\django\template\loader.py", line 62, in render_to_string
    return template.render(context, request)
  File "c:\python38\lib\site-packages\django\template\backends\django.py", line 61, in render
    return self.template.render(context)
  File "c:\python38\lib\site-packages\django\template\base.py", line 170, in render
    return self._render(context)
  File "c:\python38\lib\site-packages\django\template\base.py", line 162, in _render
    return self.nodelist.render(context)
  File "c:\python38\lib\site-packages\django\template\base.py", line 938, in render
    bit = node.render_annotated(context)
  File "c:\python38\lib\site-packages\django\template\base.py", line 905, in render_annotated
    return self.render(context)
  File "c:\python38\lib\site-packages\django\template\loader_tags.py", line 150, in render
    return compiled_parent._render(context)
  File "c:\python38\lib\site-packages\django\template\base.py", line 162, in _render
    return self.nodelist.render(context)
  File "c:\python38\lib\site-packages\django\template\base.py", line 938, in render
    bit = node.render_annotated(context)
  File "c:\python38\lib\site-packages\django\template\base.py", line 905, in render_annotated
    return self.render(context)
  File "c:\python38\lib\site-packages\django\template\loader_tags.py", line 62, in render
    result = block.nodelist.render(context)
  File "c:\python38\lib\site-packages\django\template\base.py", line 938, in render
    bit = node.render_annotated(context)
  File "c:\python38\lib\site-packages\django\template\base.py", line 905, in render_annotated
    return self.render(context)
  File "c:\python38\lib\site-packages\django\template\defaulttags.py", line 168, in render
    len_values = len(values)
  File "c:\python38\lib\site-packages\django\db\models\query.py", line 269, in __len__
    self._fetch_all()
  File "c:\python38\lib\site-packages\django\db\models\query.py", line 1303, in _fetch_all
    self._result_cache = list(self._iterable_class(self))
  File "c:\python38\lib\site-packages\django\db\models\query.py", line 53, in __iter__
    results = compiler.execute_sql(chunked_fetch=self.chunked_fetch, chunk_size=self.chunk_size)
  File "c:\python38\lib\site-packages\django\db\models\sql\compiler.py", line 1156, in execute_sql
    cursor.execute(sql, params)
  File "c:\python38\lib\site-packages\django\db\backends\utils.py", line 98, in execute
    return super().execute(sql, params)
  File "c:\python38\lib\site-packages\django\db\backends\utils.py", line 66, in execute
    return self._execute_with_wrappers(sql, params, many=False, executor=self._execute)
  File "c:\python38\lib\site-packages\django\db\backends\utils.py", line 75, in _execute_with_wrappers
    return executor(sql, params, many, context)
  File "c:\python38\lib\site-packages\django\db\backends\utils.py", line 84, in _execute
    return self.cursor.execute(sql, params)
  File "c:\python38\lib\site-packages\django\db\utils.py", line 90, in __exit__
    raise dj_exc_value.with_traceback(traceback) from exc_value
  File "c:\python38\lib\site-packages\django\db\backends\utils.py", line 84, in _execute
    return self.cursor.execute(sql, params)
  File "c:\python38\lib\site-packages\django\db\backends\sqlite3\base.py", line 413, in execute
    return Database.Cursor.execute(self, query, params)
django.db.utils.OperationalError: no such table: download_asin_task
2021-04-01 04:06:40,299 django.server ERROR    "GET /download/show_asin_task HTTP/1.1" 500 213365
2021-04-01 04:09:11,048 django.request ERROR    Internal Server Error: /download/show_asin_detail
Traceback (most recent call last):
  File "c:\python38\lib\site-packages\django\core\handlers\exception.py", line 47, in inner
    response = get_response(request)
  File "c:\python38\lib\site-packages\django\core\handlers\base.py", line 179, in _get_response
    response = wrapped_callback(request, *callback_args, **callback_kwargs)
  File "C:\Local\Work\Web\web\amazon\download\views.py", line 514, in show_asin_detail
    logger.worker.warning('log in show asin detail!')
AttributeError: 'Logger' object has no attribute 'worker'
2021-04-01 04:09:11,051 django.server ERROR    "GET /download/show_asin_detail HTTP/1.1" 500 69395
2021-04-03 05:45:10,532 django.request WARNING  Not Found: /favicon.ico
2021-04-03 05:45:10,534 django.server WARNING  "GET /favicon.ico HTTP/1.1" 404 2081
2021-04-03 06:16:58,159 django.request ERROR    Internal Server Error: /download/show_asin_task
Traceback (most recent call last):
  File "c:\python38\lib\site-packages\django\core\handlers\exception.py", line 47, in inner
    response = get_response(request)
  File "c:\python38\lib\site-packages\django\core\handlers\base.py", line 179, in _get_response
    response = wrapped_callback(request, *callback_args, **callback_kwargs)
  File "C:\Local\Work\Web\web\amazon\download\views.py", line 296, in show_asin_task
    return render(request, 'show_asin_task.html', context)
  File "c:\python38\lib\site-packages\django\shortcuts.py", line 19, in render
    content = loader.render_to_string(template_name, context, request, using=using)
  File "c:\python38\lib\site-packages\django\template\loader.py", line 62, in render_to_string
    return template.render(context, request)
  File "c:\python38\lib\site-packages\django\template\backends\django.py", line 61, in render
    return self.template.render(context)
  File "c:\python38\lib\site-packages\django\template\base.py", line 170, in render
    return self._render(context)
  File "c:\python38\lib\site-packages\django\template\base.py", line 162, in _render
    return self.nodelist.render(context)
  File "c:\python38\lib\site-packages\django\template\base.py", line 938, in render
    bit = node.render_annotated(context)
  File "c:\python38\lib\site-packages\django\template\base.py", line 905, in render_annotated
    return self.render(context)
  File "c:\python38\lib\site-packages\django\template\loader_tags.py", line 150, in render
    return compiled_parent._render(context)
  File "c:\python38\lib\site-packages\django\template\base.py", line 162, in _render
    return self.nodelist.render(context)
  File "c:\python38\lib\site-packages\django\template\base.py", line 938, in render
    bit = node.render_annotated(context)
  File "c:\python38\lib\site-packages\django\template\base.py", line 905, in render_annotated
    return self.render(context)
  File "c:\python38\lib\site-packages\django\template\loader_tags.py", line 62, in render
    result = block.nodelist.render(context)
  File "c:\python38\lib\site-packages\django\template\base.py", line 938, in render
    bit = node.render_annotated(context)
  File "c:\python38\lib\site-packages\django\template\base.py", line 905, in render_annotated
    return self.render(context)
  File "c:\python38\lib\site-packages\django\template\base.py", line 988, in render
    output = self.filter_expression.resolve(context)
  File "c:\python38\lib\site-packages\django\template\base.py", line 698, in resolve
    new_obj = func(obj, *arg_vals)
  File "c:\python38\lib\site-packages\django\template\defaultfilters.py", line 91, in json_script
    return _json_script(value, element_id)
  File "c:\python38\lib\site-packages\django\utils\html.py", line 85, in json_script
    json_str = json.dumps(value, cls=DjangoJSONEncoder).translate(_json_script_escapes)
  File "C:\Python38\lib\json\__init__.py", line 234, in dumps
    return cls(
  File "C:\Python38\lib\json\encoder.py", line 199, in encode
    chunks = self.iterencode(o, _one_shot=True)
  File "C:\Python38\lib\json\encoder.py", line 257, in iterencode
    return _iterencode(o, 0)
  File "c:\python38\lib\site-packages\django\core\serializers\json.py", line 105, in default
    return super().default(o)
  File "C:\Python38\lib\json\encoder.py", line 179, in default
    raise TypeError(f'Object of type {o.__class__.__name__} '
TypeError: Object of type dict_keys is not JSON serializable
2021-04-03 06:16:58,173 django.server ERROR    "POST /download/show_asin_task HTTP/1.1" 500 204512
2021-04-03 06:25:12,001 django.request ERROR    Internal Server Error: /download/show_asin_task
Traceback (most recent call last):
  File "c:\python38\lib\site-packages\django\core\handlers\exception.py", line 47, in inner
    response = get_response(request)
  File "c:\python38\lib\site-packages\django\core\handlers\base.py", line 179, in _get_response
    response = wrapped_callback(request, *callback_args, **callback_kwargs)
  File "C:\Local\Work\Web\web\amazon\download\views.py", line 294, in show_asin_task
    context=process_asin_json_files(plot_pk,context)
  File "C:\Local\Work\Web\web\amazon\download\asin_json_process.py", line 204, in process_asin_json_files
    print("Line No,:",log_lib.get_line_number(),context['asin_dict_list'].items())
AttributeError: 'collections.defaultdict' object has no attribute 'keiys'
2021-04-03 06:25:12,004 django.server ERROR    "POST /download/show_asin_task HTTP/1.1" 500 88876
2021-04-03 06:25:29,740 django.request ERROR    Internal Server Error: /download/show_asin_task
Traceback (most recent call last):
  File "c:\python38\lib\site-packages\django\core\handlers\exception.py", line 47, in inner
    response = get_response(request)
  File "c:\python38\lib\site-packages\django\core\handlers\base.py", line 179, in _get_response
    response = wrapped_callback(request, *callback_args, **callback_kwargs)
  File "C:\Local\Work\Web\web\amazon\download\views.py", line 294, in show_asin_task
    context=process_asin_json_files(plot_pk,context)
  File "C:\Local\Work\Web\web\amazon\download\asin_json_process.py", line 204, in process_asin_json_files
    print("Line No,:",log_lib.get_line_number(),context['asin_dict_list'].items())
AttributeError: 'collections.defaultdict' object has no attribute 'keiys'
2021-04-03 06:25:29,742 django.server ERROR    "POST /download/show_asin_task HTTP/1.1" 500 88876
2021-04-03 06:52:34,556 django.request ERROR    Internal Server Error: /download/show_asin_task
Traceback (most recent call last):
  File "c:\python38\lib\site-packages\django\core\handlers\exception.py", line 47, in inner
    response = get_response(request)
  File "c:\python38\lib\site-packages\django\core\handlers\base.py", line 179, in _get_response
    response = wrapped_callback(request, *callback_args, **callback_kwargs)
  File "C:\Local\Work\Web\web\amazon\download\views.py", line 294, in show_asin_task
    context=process_asin_json_files(plot_pk,context)
  File "C:\Local\Work\Web\web\amazon\download\asin_json_process.py", line 201, in process_asin_json_files
    asin_dict[v]= ",".join(_)
TypeError: sequence item 0: expected str instance, list found
2021-04-03 06:52:34,559 django.server ERROR    "POST /download/show_asin_task HTTP/1.1" 500 86575
2021-04-03 06:55:03,641 django.server WARNING  "GET /static/vendor/bootstrap/js/bootstrap.bundle.min.js.map HTTP/1.1" 404 1767
2021-04-03 06:57:58,804 django.server WARNING  "GET /static/vendor/bootstrap/js/bootstrap.bundle.min.js.map HTTP/1.1" 404 1767
